2024-10-17 13:59:01 Bot is not running. Restarting...
Traceback (most recent call last):
  File "/root/my_bots/football_bot/football_bot.py", line 1, in <module>
    import datetime, telebot, json, time, random, re, locale
ModuleNotFoundError: No module named 'telebot'
2024-10-17 14:00:05 Bot is not running. Restarting...
Traceback (most recent call last):
  File "/root/my_bots/football_bot/football_bot.py", line 1, in <module>
    import datetime, telebot, json, time, random, re, locale
ModuleNotFoundError: No module named 'telebot'
2024-10-17 14:01:01 Bot is not running. Restarting...
Traceback (most recent call last):
  File "/root/my_bots/football_bot/football_bot.py", line 1, in <module>
    import datetime, telebot, json, time, random, re, locale
ModuleNotFoundError: No module named 'telebot'
2024-10-17 14:02:01 Bot is not running. Restarting...
2024-10-17 14:04:02 Bot is not running. Restarting...
2024-10-17 14:48:05 Bot is not running. Restarting...
2024-10-17 18:01:06 Bot is not running. Restarting...
2024-10-19 21:43:06 Bot is not running. Restarting...
2024-10-19 21:45:01 Bot is not running. Restarting...
Traceback (most recent call last):
  File "/root/my_bots/football_bot/venv_soccer/lib/python3.12/site-packages/urllib3/connectionpool.py", line 789, in urlopen
    response = self._make_request(
               ^^^^^^^^^^^^^^^^^^^
  File "/root/my_bots/football_bot/venv_soccer/lib/python3.12/site-packages/urllib3/connectionpool.py", line 536, in _make_request
    response = conn.getresponse()
               ^^^^^^^^^^^^^^^^^^
  File "/root/my_bots/football_bot/venv_soccer/lib/python3.12/site-packages/urllib3/connection.py", line 507, in getresponse
    httplib_response = super().getresponse()
                       ^^^^^^^^^^^^^^^^^^^^^
  File "/usr/lib/python3.12/http/client.py", line 1428, in getresponse
    response.begin()
  File "/usr/lib/python3.12/http/client.py", line 331, in begin
    version, status, reason = self._read_status()
                              ^^^^^^^^^^^^^^^^^^^
  File "/usr/lib/python3.12/http/client.py", line 300, in _read_status
    raise RemoteDisconnected("Remote end closed connection without"
http.client.RemoteDisconnected: Remote end closed connection without response

During handling of the above exception, another exception occurred:

Traceback (most recent call last):
  File "/root/my_bots/football_bot/venv_soccer/lib/python3.12/site-packages/requests/adapters.py", line 667, in send
    resp = conn.urlopen(
           ^^^^^^^^^^^^^
  File "/root/my_bots/football_bot/venv_soccer/lib/python3.12/site-packages/urllib3/connectionpool.py", line 843, in urlopen
    retries = retries.increment(
              ^^^^^^^^^^^^^^^^^^
  File "/root/my_bots/football_bot/venv_soccer/lib/python3.12/site-packages/urllib3/util/retry.py", line 474, in increment
    raise reraise(type(error), error, _stacktrace)
          ^^^^^^^^^^^^^^^^^^^^^^^^^^^^^^^^^^^^^^^^
  File "/root/my_bots/football_bot/venv_soccer/lib/python3.12/site-packages/urllib3/util/util.py", line 38, in reraise
    raise value.with_traceback(tb)
  File "/root/my_bots/football_bot/venv_soccer/lib/python3.12/site-packages/urllib3/connectionpool.py", line 789, in urlopen
    response = self._make_request(
               ^^^^^^^^^^^^^^^^^^^
  File "/root/my_bots/football_bot/venv_soccer/lib/python3.12/site-packages/urllib3/connectionpool.py", line 536, in _make_request
    response = conn.getresponse()
               ^^^^^^^^^^^^^^^^^^
  File "/root/my_bots/football_bot/venv_soccer/lib/python3.12/site-packages/urllib3/connection.py", line 507, in getresponse
    httplib_response = super().getresponse()
                       ^^^^^^^^^^^^^^^^^^^^^
  File "/usr/lib/python3.12/http/client.py", line 1428, in getresponse
    response.begin()
  File "/usr/lib/python3.12/http/client.py", line 331, in begin
    version, status, reason = self._read_status()
                              ^^^^^^^^^^^^^^^^^^^
  File "/usr/lib/python3.12/http/client.py", line 300, in _read_status
    raise RemoteDisconnected("Remote end closed connection without"
urllib3.exceptions.ProtocolError: ('Connection aborted.', RemoteDisconnected('Remote end closed connection without response'))

During handling of the above exception, another exception occurred:

Traceback (most recent call last):
  File "/root/my_bots/football_bot/football_bot.py", line 667, in <module>
    bot.polling()
  File "/root/my_bots/football_bot/venv_soccer/lib/python3.12/site-packages/telebot/__init__.py", line 1198, in polling
    self.__threaded_polling(non_stop=non_stop, interval=interval, timeout=timeout, long_polling_timeout=long_polling_timeout,
  File "/root/my_bots/football_bot/venv_soccer/lib/python3.12/site-packages/telebot/__init__.py", line 1273, in __threaded_polling
    raise e
  File "/root/my_bots/football_bot/venv_soccer/lib/python3.12/site-packages/telebot/__init__.py", line 1234, in __threaded_polling
    polling_thread.raise_exceptions()
  File "/root/my_bots/football_bot/venv_soccer/lib/python3.12/site-packages/telebot/util.py", line 111, in raise_exceptions
    raise self.exception_info
  File "/root/my_bots/football_bot/venv_soccer/lib/python3.12/site-packages/telebot/util.py", line 93, in run
    task(*args, **kwargs)
  File "/root/my_bots/football_bot/venv_soccer/lib/python3.12/site-packages/telebot/__init__.py", line 688, in __retrieve_updates
    updates = self.get_updates(offset=(self.last_update_id + 1), 
              ^^^^^^^^^^^^^^^^^^^^^^^^^^^^^^^^^^^^^^^^^^^^^^^^^^
  File "/root/my_bots/football_bot/venv_soccer/lib/python3.12/site-packages/telebot/__init__.py", line 660, in get_updates
    json_updates = apihelper.get_updates(
                   ^^^^^^^^^^^^^^^^^^^^^^
  File "/root/my_bots/football_bot/venv_soccer/lib/python3.12/site-packages/telebot/apihelper.py", line 330, in get_updates
    return _make_request(token, method_url, params=payload)
           ^^^^^^^^^^^^^^^^^^^^^^^^^^^^^^^^^^^^^^^^^^^^^^^^
  File "/root/my_bots/football_bot/venv_soccer/lib/python3.12/site-packages/telebot/apihelper.py", line 162, in _make_request
    result = _get_req_session().request(
             ^^^^^^^^^^^^^^^^^^^^^^^^^^^
  File "/root/my_bots/football_bot/venv_soccer/lib/python3.12/site-packages/requests/sessions.py", line 589, in request
    resp = self.send(prep, **send_kwargs)
           ^^^^^^^^^^^^^^^^^^^^^^^^^^^^^^
  File "/root/my_bots/football_bot/venv_soccer/lib/python3.12/site-packages/requests/sessions.py", line 703, in send
    r = adapter.send(request, **kwargs)
        ^^^^^^^^^^^^^^^^^^^^^^^^^^^^^^^
  File "/root/my_bots/football_bot/venv_soccer/lib/python3.12/site-packages/requests/adapters.py", line 682, in send
    raise ConnectionError(err, request=request)
requests.exceptions.ConnectionError: ('Connection aborted.', RemoteDisconnected('Remote end closed connection without response'))
2024-10-25 10:44:02 Bot is not running. Restarting...
